Workbook

Sheet Methodology
B1: GovUX Scoring Model — Parameters & How the Score Is Computed
B2: Aligned to UX4G (MeitY/NeGD) audit parameters, WCAG 2.2 AA, GIGW 3.0 and Google Core Web Vitals. Every website score is fully traceable to the parameters below.
B4: The scoring logic — in plain terms
B5: 1. Every parameter is measured on a 0–100 scale (a pass-rate, a normalised metric, or a rubric score).
B6: 2. Parameters roll up into a Category Score = the weighted average of that category's parameters (weights shown in the model).
B7: 3. The overall GovUX Score = the weighted sum of the eight Category Scores. Category weights reflect citizen impact and legal obligation and sum to 100%.
B8: 4. The score maps to a band: A 90–100 Exemplary · B 75–89 Strong · C 60–74 Needs work · D 40–59 At risk · E below 40 Critical.
B9: 5. Guard-rail: a critical accessibility or security failure (e.g. keyboard-inoperable, or no HTTPS) CAPS the attainable band at C until fixed — because these are legal, not cosmetic, failures.
B11: Category weights (why they are what they are)
B12: • Accessibility 22% and GIGW 15% carry the most weight because they are legal duties (RPwD Act, GIGW mandate).
B13: • Usability & UX 17% and Design foundation 11% capture the UX4G core — whether citizens can actually complete tasks.
B14: • Performance 12% and Responsiveness & Compatibility 10% reflect that citizens use varied devices, screen sizes and browsers on constrained networks (responsive, multi-browser and multi-device-size checks).
... B22: The 'Score Summary' sheet shows the category roll-up, the final score, the band, and whether the guard-rail is active.

Sheet Scoring Model
A1: Category / Parameter | B1: How it is scored (what 'good' looks like) | C1: Wt % | D1: Measured (0-100) | E1: Weighted | F1: Tool | G1: Auto
A2: Accessibility (WCAG 2.2 AA) | C2: 22% wt
A3: Colour contrast (1.4.3) | B3: % of text meeting 4.5:1 (3:1 large) | C3: 15 | D3: 55 | E3: =C3*D3/100 -> 8.25 | F3: axe-core | G3: Full
A4: Alt text present & meaningful | B4: Images have alt AND it describes them | C4: 12 | D4: 52 | E4: =C4*D4/100 -> 6.24 | F4: axe-core + VLM | G4: Part
A5: Keyboard operability (2.1.1) | B5: All functions usable by keyboard, no traps | C5: 14 | D5: 40 | E5: =C5*D5/100 -> 5.6 | F5: Playwright + manual | G5: Part
A6: Form labels & instructions | B6: Inputs have programmatic labels/help | C6: 10 | D6: 68 | E6: =C6*D6/100 -> 6.8 | F6: axe-core | G6: Full
A7: Headings & structure (1.3.1) | B7: Logical headings, no skipped levels | C7: 8 | D7: 72 | E7: =C7*D7/100 -> 5.76 | F7: axe-core | G7: Full
A8: ARIA & semantics (4.1.2) | B8: Valid roles, names, landmarks | C8: 8 | D8: 70 | E8: =C8*D8/100 -> 5.6 | F8: axe-core | G8: Full
A9: Focus visible & order (2.4.7/2.4.11) | B9: Visible focus, sensible order | C9: 8 | D9: 58 | E9: =C9*D9/100 -> 4.64 | F9: Playwright + manual | G9: Part
A10: Target size (2.5.8) | B10: Tap/click targets >= 24px | C10: 6 | D10: 64 | E10: =C10*D10/100 -> 3.84 | F10: Playwright geometry | G10: Part
A11: Media alternatives (1.2.x) | B11: Captions/transcripts present & correct | C11: 5 | D11: 50 | E11: =C11*D11/100 -> 2.5 | F11: DOM + manual | G11: Part
A12: Language attributes (3.1.1) | B12: html lang correct; parts tagged | C12: 4 | D12: 80 | E12: =C12*D12/100 -> 3.2 | F12: axe-core | G12: Full
A13: Accessible authentication (3.3.8) | B13: No cognitive-only login test | C13: 5 | D13: 60 | E13: =C13*D13/100 -> 3 | F13: manual | G13: Man
A14: Screen-reader pass | B14: Key journeys work with NVDA/TalkBack | C14: 5 | D14: 48 | E14: =C14*D14/100 -> 2.4 | F14: NVDA testing | G14: Man
A15: → Category score | B15: weighted average of parameters above | C15: =SUM(C3:C14) -> 100 | D15: =SUMPRODUCT(C3:C14,D3:D14)/SUM(C3:C14) -> 57.83
A17: Usability & UX heuristics | C17: 17% wt
A18: Navigation clarity & IA | B18: Intuitive menus, shallow paths, breadcrumbs | C18: 16 | D18: 66 | E18: =C18*D18/100 -> 10.56 | F18: DOM + LLM/manual | G18: Part
A19: Visibility of system status | B19: Clear feedback on every action | C19: 10 | D19: 62 | E19: =C19*D19/100 -> 6.2 | F19: manual | G19: Man
A20: Match to real world / plain labels | B20: Citizen language, not jargon | C20: 10 | D20: 58 | E20: =C20*D20/100 -> 5.8 | F20: LLM + manual | G20: Part
A21: User control & freedom | B21: Undo, back, escape hatches | C21: 8 | D21: 70 | E21: =C21*D21/100 -> 5.6 | F21: manual | G21: Man
A22: Consistency & standards | B22: Consistent patterns across the site | C22: 10 | D22: 72 | E22: =C22*D22/100 -> 7.2 | F22: DOM diff | G22: Part
A23: Error prevention | B23: Guards against mistakes before they happen | C23: 8 | D23: 60 | E23: =C23*D23/100 -> 4.8 | F23: manual | G23: Man
A24: Recognition over recall | B24: Options visible, low memory load | C24: 7 | D24: 66 | E24: =C24*D24/100 -> 4.62 | F24: manual | G24: Man
A25: Flexibility & efficiency | B25: Shortcuts/accelerators for repeat tasks | C25: 6 | D25: 64 | E25: =C25*D25/100 -> 3.84 | F25: manual | G25: Man
A26: Search effectiveness | B26: Tolerant search, useful results, no dead-ends | C26: 10 | D26: 55 | E26: =C26*D26/100 -> 5.5 | F26: query probes | G26: Part
A27: Form usability | B27: Few fields, inline validation, clear help | C27: 10 | D27: 68 | E27: =C27*D27/100 -> 6.8 | F27: DOM heuristics | G27: Part
A28: Help & documentation | B28: Findable, task-focused help | C28: 5 | D28: 72 | E28: =C28*D28/100 -> 3.6 | F28: DOM + manual | G28: Part
A29: → Category score | B29: weighted average of parameters above | C29: =SUM(C18:C28) -> 100 | D29: =SUMPRODUCT(C18:C28,D18:D28)/SUM(C18:C28) -> 64.52
A31: Design foundation & consistency (UX4G) | C31: 11% wt
A32: Typography system & legibility | B32: Consistent, legible type scale | C32: 18 | D32: 74 | E32: =C32*D32/100 -> 13.32 | F32: CSS parse | G32: Part
A33: Colour system & usage | B33: Consistent, accessible palette | C33: 16 | D33: 70 | E33: =C33*D33/100 -> 11.2 | F33: screenshot analysis | G33: Part
A34: Layout, grid & spacing | B34: Aligned grid, adequate whitespace | C34: 16 | D34: 66 | E34: =C34*D34/100 -> 10.56 | F34: CSS/visual | G34: Part
A35: Visual hierarchy | B35: Clear focal order, scannable | C35: 14 | D35: 60 | E35: =C35*D35/100 -> 8.4 | F35: VLM + manual | G35: Man
A36: Design-system adherence | B36: Uses UX4G/standard components | C36: 16 | D36: 58 | E36: =C36*D36/100 -> 9.28 | F36: DOM class + diff | G36: Part
A37: Iconography & imagery | B37: Consistent, meaningful visuals | C37: 10 | D37: 72 | E37: =C37*D37/100 -> 7.2 | F37: visual review | G37: Man
A38: Cross-page consistency | B38: Same patterns site-wide | C38: 10 | D38: 68 | E38: =C38*D38/100 -> 6.8 | F38: DOM/visual diff | G38: Part
A39: → Category score | B39: weighted average of parameters above | C39: =SUM(C32:C38) -> 100 | D39: =SUMPRODUCT(C32:C38,D32:D38)/SUM(C32:C38) -> 66.76
A41: GIGW 3.0 mandatory compliance | C41: 15% wt
A42: Mandatory footer elements | B42: Contact, policies, copyright, T&C present | C42: 20 | D42: 78 | E42: =C42*D42/100 -> 15.6 | F42: lxml/keyword | G42: Full
A43: Last-updated & content currency | B43: Freshness stamps; no stale pages | C43: 10 | D43: 64 | E43: =C43*D43/100 -> 6.4 | F43: regex + manual | G43: Part
...

Sheet Phase-1 ML Plan
A1: Phase-1 ML / Computer-Vision Plan — classical models only, no LLM
A3: These 8 components use classical machine learning and computer vision (NO large language models). They are self-hosted, explainable, run on modest CPU/GPU, and need no external API — so they fit government data-residency rules.
A4: Purpose: upgrade the parameters currently marked 'Partial / Manual' in the Scoring Model into automatable, ML-scored checks. This lifts automatable coverage from ~68% (rules only) to ~85% — with no LLM.
A5: How they plug in: each model outputs a 0–100 sub-score that feeds the same 'Measured' column of the Scoring Model, with low-confidence cases routed to human spot-check.
A7: ID | B7: ML component | C7: Model type | D7: Inputs / features | E7: Output | F7: Parameters it upgrades | G7: Library (open-source) | H7: Training data | I7: CPU/GPU
A8: M1 | B8: Priority & impact ranking | C8: Gradient-boosted trees (XGBoost/LightGBM) | D8: severity, guideline, page traffic, #affected elements, effort est., past-fix outcomes | E8: ranked impact x effort per finding | F8: All categories — report prioritisation | G8: XGBoost / scikit-learn | H8: labelled past audits + remediation outcomes | I8: CPU
A9: M2 | B9: Decorative vs informative image classifier | C9: CNN transfer learning (MobileNetV3 / ResNet50) | D9: image crops from pages | E9: decorative / informative + confidence | F9: Accessibility — alt-text triage (A02) | G9: PyTorch + timm | H9: labelled gov-site images | I9: GPU (light)
A10: M3 | B10: Visual layout & hierarchy analyzer | C10: Object/element detection + CV heuristics | D10: full-page screenshots | E10: element map, whitespace ratio, alignment & saliency-based hierarchy score | F10: Design — layout, visual hierarchy, clutter | G10: Detectron2 / YOLOv8 + OpenCV / scikit-image | H10: pretrained detector; optional UI fine-tune | I10: GPU (light)
A11: M4 | B11: Colour & typography consistency | C11: k-means clustering + CSS parsing | D11: screenshots + computed styles | E11: palette size, off-palette %, type-scale consistency, contrast map | F11: Design — colour system, typography | G11: scikit-learn, tinycss2, OpenCV | H11: unsupervised + design-system reference | I11: CPU
A12: M5 | B12: Cross-page consistency | C12: Structural hashing + SSIM | D12: DOM trees + screenshots across pages | E12: consistency score, outlier pages | F12: Design & UX — consistency | G12: scikit-image (SSIM), datasketch/simhash | H12: none (unsupervised) | I12: CPU
A13: M6 | B13: Plain-language / jargon classifier | C13: TF-IDF + linear SVM / logistic reg. (classical NLP) | D13: page text | E13: plain-language score, flagged jargon sentences | F13: Content clarity; UX plain labels | G13: scikit-learn, spaCy, textstat | H13: labelled plain vs complex gov text | I13: CPU
A14: M7 | B14: Language & script detection | C14: fastText / CLD3 classifier | D14: page text | E14: language(s), script, coverage vs required Indic set | F14: GIGW & Content — multilingual | G14: fastText, AI4Bharat Indic NLP | H14: pretrained | I14: CPU
A15: M8 | B15: Score regression & anomaly detection | C15: Isolation Forest / time-series change detection | D15: historical category & overall scores per domain | E15: regression alerts, anomaly flags | F15: National dashboard alerts; re-audit trends | G15: scikit-learn (IsolationForest), statsmodels/Prophet | H15: historical audit scores | I15: CPU
A17: Sequencing within Phase 1
A18: Sprint 1 (quick wins, low data need) | C18: M7 Language detection · M8 Regression/anomaly · M1 Priority ranking — pretrained or small models; immediate value on reports & dashboard.
A19: Sprint 2 (needs labelling) | C19: M2 Decorative-image classifier · M6 Plain-language classifier — build a labelled dataset from gov sites first.
A20: Sprint 3 (computer vision) | C20: M3 Layout & hierarchy · M4 Colour/typography · M5 Cross-page consistency — screenshot pipeline + light GPU.
A22: Outcome of Phase-1 ML: rules-only automation (~68%) + these classical models raises automatable coverage to ~85% with NO LLM. The remaining ~15% (true reading-order sense, nuanced clarity, screen-reader journeys) stays with human review until/unless an LLM layer is added in a later phase. Every model outputs an explainable sub-score with a confidence; low-confidence results are auto-routed to a human, preserving the reproducible, auditable scoring required by the platform.

Sheet Score Summary
A1: GovUX Score — computed from the model
A3: Category | B3: Category weight % | C3: Category score (0-100) | D3: Contribution to overall
A4: Accessibility (WCAG 2.2 AA) | B4: 22 | C4: ='Scoring Model'!D15 -> 57.83 | D4: =B4*C4/100 -> 12.7226
A5: Usability & UX heuristics | B5: 17 | C5: ='Scoring Model'!D29 -> 64.52 | D5: =B5*C5/100 -> 10.9684
A6: Design foundation & consistency (UX4G) | B6: 11 | C6: ='Scoring Model'!D39 -> 66.76 | D6: =B6*C6/100 -> 7.3436
A7: GIGW 3.0 mandatory compliance | B7: 15 | C7: ='Scoring Model'!D50 -> 71.62 | D7: =B7*C7/100 -> 10.743
A8: Performance & Core Web Vitals | B8: 12 | C8: ='Scoring Model'!D60 -> 61.76 | D8: =B8*C8/100 -> 7.4112
A9: Content quality & readability | B9: 7 | C9: ='Scoring Model'!D69 -> 61.32 | D9: =B9*C9/100 -> 4.2924
A10: Responsiveness & Compatibility | B10: 10 | C10: ='Scoring Model'!D79 -> 61.16 | D10: =B10*C10/100 -> 6.116
A11: Trust, security & privacy | B11: 6 | C11: ='Scoring Model'!D88 -> 70.9 | D11: =B11*C11/100 -> 4.254
A12: OVERALL GovUX SCORE | B12: =SUM(B4:B11) -> 100 | D12: =SUM(D4:D11) -> 63.8512
A14: Band | B14: =IF(D12>=90,"A — Exemplary",IF(D12>=75,"B — Strong",IF(D12>=60,"C — Needs work",IF(D12>=40,"D — At risk","E — Critical")))) -> C — Needs work
A15: Guard-rail | B15: =IF(OR(INDEX('Scoring Model'!D:D,MATCH("*Keyboard operability*",'Scoring Model'!A:A,0))<50,INDEX('Scoring Model'!D:D,MATCH("*HTTPS & domain*",'Scoring Model'!A:A,0))<50),"ACTIVE — critical failure caps band at C until fixed","Not triggered") -> ACTIVE — critical failure caps band at C until fixed
A17: This score is fully traceable: change any 'Measured' value in the Scoring Model sheet and the category scores, overall score and band recompute here. Weights are configurable and version-controlled.
